Workbook

Sheet Historical
A1: ALKEM LABORATORIES LIMITED
A2: Historical Financial Information
A4: Income Statement | E4: Unit | F4: 2019 | G4: 2020 | H4: 2021 | I4: 2022 | J4: 2023
D5: INCOME
D6: (a) Revenue from operations | E6: ₹ MM | F6: 73572 | G6: 83444 | H6: 88650 | I6: 106342 | J6: 115993
D7: (b) Other income | E7: ₹ MM | F7: 877 | G7: 1042 | H7: 2332 | I7: 1477 | J7: 1131
D8: Total Income | E8: ₹ MM | F8: =SUM(F6:F7) -> 74449 | G8: =SUM(G6:G7) -> 84486 | H8: =SUM(H6:H7) -> 90982 | I8: =SUM(I6:I7) -> 107819 | J8: =SUM(J6:J7) -> 117124
D10: EXPENSES
D11: (a) Cost of materials consumed | E11: ₹ MM | F11: 18111 | G11: 21318 | H11: 23945 | I11: 32261 | J11: 30569
D12: (b) Purchases of stock-in-trade | E12: ₹ MM | F12: 11302 | G12: 14431 | H12: 14378 | I12: 14897 | J12: 13876
D13: (c) Changes in inventories of finished goods, work-in-progress and stock-in-trade | E13: ₹ MM | F13: 36 | G13: -2300 | H13: -3338 | I13: -5355 | J13: 4624
D14: (d) Employee benefits expense | E14: ₹ MM | F14: 13625 | G14: 15055 | H14: 16210 | I14: 19627 | J14: 21314
D15: (e) Finance costs | E15: ₹ MM | F15: 546 | G15: 651 | H15: 589 | I15: 524 | J15: 1074
D16: (f) Depreciation and amortisation expense | E16: ₹ MM | F16: 1932 | G16: 2528 | H16: 2746 | I16: 3040 | J16: 3104
D17: (g) Other expenses | E17: ₹ MM | F17: 19350 | G17: 20205 | H17: 18031 | I17: 24383 | J17: 29516
D18: Total Expenses | E18: ₹ MM | F18: =SUM(F11:F17) -> 64902 | G18: =SUM(G11:G17) -> 71888 | H18: =SUM(H11:H17) -> 72561 | I18: =SUM(I11:I17) -> 89377 | J18: =SUM(J11:J17) -> 104077
D20: Profit before exceptional items and tax (1) - (2) | E20: =E18 -> ₹ MM | F20: =F8-F18 -> 9547 | G20: =G8-G18 -> 12598 | H20: =H8-H18 -> 18421 | I20: =I8-I18 -> 18442 | J20: =J8-J18 -> 13047
D21: Exceptional items | F21: 0 | G21: 0 | H21: 0 | I21: -150 | J21: -1030
D22: Profit before tax (3) + (4) | F22: =SUM(F20:F21) -> 9547 | G22: =SUM(G20:G21) -> 12598 | H22: =SUM(H20:H21) -> 18421 | I22: =SUM(I20:I21) -> 18292 | J22: =SUM(J20:J21) -> 12017
D24: TAX EXPENSE
D25: (a) Current tax | F25: 2292 | G25: 3543 | H25: 3965 | I25: 3620 | J25: 2739
D26: (b) Deferred tax charge / (credit) (net) | F26: -482 | G26: -2124 | H26: -1722 | I26: -1980 | J26: 241
D27: Tax adjustment of earlier periods | F27: 0 | G27: -314 | H27: 0 | I27: 0 | J27: 0
D28: Total tax expenses (a + b) | F28: =F25+F26+F27 -> 1810 | G28: =G25+G26+G27 -> 1105 | H28: =H25+H26+H27 -> 2243 | I28: =I25+I26+I27 -> 1640 | J28: =J25+J26+J27 -> 2980
D30: Profit for the year (5) - (6) | F30: =F22-F28 -> 7737 | G30: =G22-G28 -> 11493 | H30: =H22-H28 -> 16178 | I30: =I22-I28 -> 16652 | J30: =J22-J28 -> 9037
D31: Profit attributable to Non-Controlling Interest | F31: 131 | G31: 131 | H31: 131 | I31: 131 | J31: 131
D32: Profit attributable to Owners of the Company (7) - (8) | F32: =F30-F31 -> 7606 | G32: =G30-G31 -> 11362 | H32: =H30-H31 -> 16047 | I32: =I30-I31 -> 16521 | J32: =J30-J31 -> 8906
A35: Balance Sheet | E35: Unit | F35: 2019 | G35: 2020 | H35: 2021 | I35: 2022 | J35: 2023
D36: ASSETS
D37: Non-current assets
D38: (a) Property, plant and equipment | F38: 21056.2 | G38: 23062.9 | H38: 22339.3 | I38: 22871 | J38: 20654
D39: Right of use assets | J39: 1378.5
D40: (b) Capital work in progress | F40: 4929.6 | G40: 3629.7 | H40: 3932.8 | I40: 3394.8 | J40: 3102.7
D41: (c) Goodwill | F41: 231.5 | G41: 259.3 | H41: 3953.9 | I41: 4030.9 | J41: 4131.7
D42: (d) Other intangible assets | F42: 442.6 | G42: 2032.7 | H42: 1636.6 | I42: 2115.4 | J42: 664.1
D43: (e) Goodwill on consolidation | F43: 3574.1 | G43: 3725.2 | H43: 0 | I43: 0 | J43: 0
D44: Intangible assets under development | J44: 129.7
D45: (f) Financial assets
D46: (i) Investments | F46: 957.4 | G46: 915 | H46: 1539.5 | I46: 2316.7 | J46: 3046.1
D47: (ii) Loans | F47: 136.3 | G47: 106.1 | H47: 80.2 | I47: 80.2 | J47: 80.2
...

Sheet Model
A1: ALKEM LABORATORIES LIMITED | I1: Historical Period | M1: Forecast Period
A2: Financial Statement & DCF Analysis
G3: 2019 | H3: 2020 | I3: 2021 | J3: 2022 | K3: 2023 | L3: 2024 | M3: 2025 | N3: 2026 | O3: 2027 | P3: 2028
A5: Ratios & Assumptions | F5: Units | R5: Scenarios | T5: Growth Rate
D6: =R5 -> Scenarios | E6: Base Case | G6: =IF(E6=R8,1,IF(E6=R9,2,3)) -> 1
D7: Revenue Growth | F7: % | H7: =H24/G24-1 -> 0.13418148 | I7: =I24/H24-1 -> 0.062389147 | J7: =J24/I24-1 -> 0.19957135 | K7: =K24/J24-1 -> 0.090754359 | L7: {=CHOOSE(G6,U8:Y8,U9:Y9,U10:Y10)} -> 0.12172408 | M7: 0.10346547 | N7: 0.087945651 | O7: 0.074753803 | P7: 0.063540733 | R7: Scenario | S7: Description | T7: Rate | U7: 2024 | V7: 2025 | W7: 2026 | X7: 2027 | Y7: 2028
D8: Cost of Good Sold (% of Revenue) | F8: % | G8: =-G25/G24 -> 0.40027456 | H8: =-H25/H24 -> 0.40085566 | I8: =-I25/I24 -> 0.39464185 | J8: =-J25/J24 -> 0.39309962 | K8: =-K25/K24 -> 0.42303415 | L8: =AVERAGE(G8:K8) -> 0.40238117 | M8: =L8 -> 0.40238117 | N8: =M8 -> 0.40238117 | O8: =N8 -> 0.40238117 | P8: =O8 -> 0.40238117 | R8: Base Case | S8: Average growth rate from the past four years | T8: =AVERAGE(H7:K7) -> 0.12172408 | U8: {=T8:T10} -> 0.12172408 | V8: =U8*(1-$T$12) -> 0.10346547 | W8: =V8*(1-$T$12) -> 0.087945651 | X8: =W8*(1-$T$12) -> 0.074753803 | Y8: =X8*(1-$T$12) -> 0.063540733
D9: Salaries and benefits (% of Revenue) | F9: % | G9: =-G28/G24 -> 0.18519274 | H9: =-H28/H24 -> 0.1804204 | I9: =-I28/I24 -> 0.18285392 | J9: =-J28/J24 -> 0.18456489 | K9: =-K28/K24 -> 0.18375247 | L9: =AVERAGE(G9:K9) -> 0.18335688 | M9: =L9 -> 0.18335688 | N9: =M9 -> 0.18335688 | O9: =N9 -> 0.18335688 | P9: =O9 -> 0.18335688 | R9: Bull Case | S9: Maximum growth rate demonstrated by the company | T9: =MAX(H7:K7) -> 0.19957135 | U9: 0.19957135 | V9: =U9*(1-$T$12) -> 0.16963565 | W9: =V9*(1-$T$12) -> 0.1441903 | X9: =W9*(1-$T$12) -> 0.12256175 | Y9: =X9*(1-$T$12) -> 0.10417749
D10: Other SG&A Expenses (% of Revenue) | F10: % | G10: =-G29/G24 -> 0.26300767 | H10: =-H29/H24 -> 0.24213844 | I10: =-I29/I24 -> 0.20339538 | J10: =-J29/J24 -> 0.22928852 | K10: =-K29/K24 -> 0.25446363 | L10: =AVERAGE(G10:K10) -> 0.23845873 | M10: =L10 -> 0.23845873 | N10: =M10 -> 0.23845873 | O10: =N10 -> 0.23845873 | P10: =O10 -> 0.23845873 | R10: Bear Case | S10: Minimum growth rate experienced by the company | T10: =MIN(H7:K7) -> 0.062389147 | U10: 0.062389147 | V10: =U10*(1-$T$12) -> 0.053030775 | W10: =V10*(1-$T$12) -> 0.045076159 | X10: =W10*(1-$T$12) -> 0.038314735 | Y10: =X10*(1-$T$12) -> 0.032567525
D11: Depreciation & Amortization Expenses (% of PP&E) | F11: % | H11: =-H31/H107 -> 0.095654675 | I11: =-I31/I107 -> 0.095595172 | J11: =-J31/J107 -> 0.10892661 | K11: =-K31/K107 -> 0.10936817 | L11: =AVERAGE(G11:K11) -> 0.10238616 | M11: =L11 -> 0.10238616 | N11: =M11 -> 0.10238616 | O11: =N11 -> 0.10238616 | P11: =O11 -> 0.10238616
D12: Interest (% of Debt) | F12: % | H12: =-H33/H113 -> 0.07212737 | I12: =-I33/I113 -> 0.035423245 | J12: =-J33/J113 -> 0.029241071 | K12: =-K33/K113 -> 0.040251855 | L12: =AVERAGE(G12:K12) -> 0.044260885 | M12: =L12 -> 0.044260885 | N12: =M12 -> 0.044260885 | O12: =N12 -> 0.044260885 | P12: =O12 -> 0.044260885 | R12: Active Scenario | T12: 0.15
D13: Other Income (Expenses) (% of Revenue) | F13: % | G13: =G34/G24 -> 0.011920296 | H13: =H34/H24 -> 0.012487417 | I13: =I34/I24 -> 0.026305697 | J13: =J34/J24 -> 0.01388915 | K13: =K34/K24 -> 0.0097505884 | L13: =AVERAGE(G13:K13) -> 0.01487063 | M13: =L13 -> 0.01487063 | N13: =M13 -> 0.01487063 | O13: =N13 -> 0.01487063 | P13: =O13 -> 0.01487063
D14: Tax Rate (% of Earnings before Tax) | F14: % | G14: =-G36/G35 -> 0.18958835 | H14: =-H36/H35 -> 0.087712335 | I14: =-I36/I35 -> 0.12176321 | J14: =-J36/J35 -> 0.088927448 | K14: =-K36/K35 -> 0.228405 | L14: =AVERAGE(G14:K14) -> 0.14327927 | M14: =L14 -> 0.14327927 | N14: =M14 -> 0.14327927 | O14: =N14 -> 0.14327927 | P14: =O14 -> 0.14327927
D15: Dividends Payout | F15: % | G15: =-G89/G37 -> 0.2825126 | H15: =-H89/H37 -> 0.38245889 | I15: =-I89/I37 -> 0.20693534 | J15: =-J89/J37 -> 0.25110701 | K15: =-K89/K37 -> 0.52599583 | L15: =AVERAGE(G15:K15) -> 0.32980193 | M15: =L15 -> 0.32980193 | N15: =M15 -> 0.32980193 | O15: =N15 -> 0.32980193 | P15: =O15 -> 0.32980193
D16: Accounts Receivable | F16: =F17 -> Days | G16: =G44/G24*365 -> 61.9352 | H16: =H44/H24*365 -> 72.146158 | I16: =I44/I24*365 -> 66.173903 | J16: =J44/J24*365 -> 64.685543 | K16: =K44/K24*365 -> 67.094195 | L16: =AVERAGE(G16:K16) -> 66.407 | M16: =L16 -> 66.407 | N16: =M16 -> 66.407 | O16: =N16 -> 66.407 | P16: =O16 -> 66.407
D17: Inventory | F17: =F18 -> Days | G17: =G45/-G25*365 -> 185.89852 | H17: =H45/-H25*365 -> 198.47209 | I17: =I45/-I25*365 -> 241.25785 | J17: =J45/-J25*365 -> 262.42577 | K17: =K45/-K25*365 -> 193.96125 | L17: =AVERAGE(G17:K17) -> 216.4031 | M17: =L17 -> 216.4031 | N17: =M17 -> 216.4031 | O17: =N17 -> 216.4031 | P17: =O17 -> 216.4031
D18: Accounts Payable | F18: Days | G18: =(Historical!F93+Historical!F94)/-G25*365 -> 119.26424 | H18: =(Historical!G93+Historical!G94)/-H25*365 -> 104.10722 | I18: =(Historical!H93+Historical!H94)/-I25*365 -> 111.572 | J18: =(Historical!I93+Historical!I94)/-J25*365 -> 102.45286 | K18: =(Historical!J93+Historical!J94)/-K25*365 -> 86.659327 | L18: =AVERAGE(G18:K18) -> 104.81113 | M18: =L18 -> 104.81113 | N18: =M18 -> 104.81113 | O18: =N18 -> 104.81113 | P18: =O18 -> 104.81113
D19: Capital Asset Turnover Ratio | F19: Times | G19: =G24/G49 -> 2.7838235 | H19: =H24/H49 -> 2.9048957 | I19: =I24/I49 -> 3.1764289 | J19: =J24/J49 -> 3.746917 | K19: =K24/K49 -> 4.4734853 | L19: =K19+0.5 -> 4.9734853 | M19: =L19+0.5 -> 5.4734853 | N19: =M19+0.5 -> 5.9734853 | O19: =N19+0.5 -> 6.4734853 | P19: =O19+0.5 -> 6.9734853
A22: Income Statement | F22: Units | G22: 2019 | H22: 2020 | I22: 2021 | J22: 2022 | K22: 2023 | L22: 2024 | M22: 2025 | N22: 2026 | O22: 2027 | P22: 2028
D23: Income
D24: Revenue | G24: =Historical!F6 -> 73572 | H24: =Historical!G6 -> 83444 | I24: =Historical!H6 -> 88650 | J24: =Historical!I6 -> 106342 | K24: =Historical!J6 -> 115993 | L24: =K24*(1+L7) -> 130112.14 | M24: =L24*(1+M7) -> 143574.26 | N24: =M24*(1+N7) -> 156200.99 | O24: =N24*(1+O7) -> 167877.6 | P24: =O24*(1+P7) -> 178544.67
D25: Cold of Good Sold (COGS) | G25: =-(Historical!F11+Historical!F12+Historical!F13) -> -29449 | H25: =-(Historical!G11+Historical!G12+Historical!G13) -> -33449 | I25: =-(Historical!H11+Historical!H12+Historical!H13) -> -34985 | J25: =-(Historical!I11+Historical!I12+Historical!I13) -> -41803 | K25: =-(Historical!J11+Historical!J12+Historical!J13) -> -49069 | L25: =-L24*L8 -> -52354.676 | M25: =-M24*M8 -> -57771.577 | N25: =-N24*N8 -> -62852.336 | O25: =-O24*O8 -> -67550.787 | P25: =-P24*P8 -> -71843.013
D26: Gross profit | G26: =SUM(G24:G25) -> 44123 | H26: =SUM(H24:H25) -> 49995 | I26: =SUM(I24:I25) -> 53665 | J26: =SUM(J24:J25) -> 64539 | K26: =SUM(K24:K25) -> 66924 | L26: =SUM(L24:L25) -> 77757.466 | M26: =SUM(M24:M25) -> 85802.679 | N26: =SUM(N24:N25) -> 93348.651 | ... P26: =SUM(P24:P25) -> 106701.66
D27: Expenses
D28: Salary and benefits | G28: =-Historical!F14 -> -13625 | H28: =-Historical!G14 -> -15055 | I28: =-Historical!H14 -> -16210 | J28: =-Historical!I14 -> -19627 | K28: =-Historical!J14 -> -21314 | L28: =-L24*L9 -> -23856.957 | M28: =-M24*M9 -> -26325.328 | N28: =-N24*N9 -> -28640.526 | O28: =-O24*O9 -> -30781.515 | P28: =-P24*P9 -> -32737.395
D29: Other SG&A Expenses | G29: =-Historical!F17 -> -19350 | H29: =-Historical!G17 -> -20205 | I29: =-Historical!H17 -> -18031 | J29: =-Historical!I17 -> -24383 | K29: =-Historical!J17 -> -29516 | L29: =-L24*L10 -> -31026.376 | M29: =-M24*M10 -> -34236.534 | N29: =-N24*N10 -> -37247.489 | O29: =-O24*O10 -> -40031.88 | P29: =-P24*P10 -> -42575.535
D30: EBITDA | G30: =G26+SUM(G28:G29) -> 11148 | H30: =H26+SUM(H28:H29) -> 14735 | I30: =I26+SUM(I28:I29) -> 19424 | J30: =J26+SUM(J28:J29) -> 20529 | K30: =K26+SUM(K28:K29) -> 16094 | L30: =L26+SUM(L28:L29) -> 22874.133 | M30: =M26+SUM(M28:M29) -> 25240.816 | N30: =N26+SUM(N28:N29) -> 27460.636 | ... P30: =P26+SUM(P28:P29) -> 31388.728
D31: Depreciation & Amortization Expenses | G31: =-Historical!F16 -> -1932 | H31: =-Historical!G16 -> -2528 | I31: =-Historical!H16 -> -2746 | J31: =-Historical!I16 -> -3040 | K31: =-Historical!J16 -> -3104 | L31: =-L107*L11 -> -2654.7707 | M31: =-M107*M11 -> -2662.4168 | N31: =-N107*N11 -> -2669.2801 | O31: =-O107*O11 -> -2675.4406 | P31: =-P107*P11 -> -2680.9704
D32: EBIT | G32: =G30+G31 -> 9216 | H32: =H30+H31 -> 12207 | I32: =I30+I31 -> 16678 | J32: =J30+J31 -> 17489 | K32: =K30+K31 -> 12990 | L32: =L30+L31 -> 20219.363 | M32: =M30+M31 -> 22578.4 | N32: =N30+N31 -> 24791.356 | ... P32: =P30+P31 -> 28707.758
D33: Interest | G33: =-Historical!F15 -> -546 | H33: =-Historical!G15 -> -651 | I33: =-Historical!H15 -> -589 | J33: =-Historical!I15 -> -524 | K33: =-Historical!J15 -> -1074 | L33: =-L113*L12 -> -618.18293 | M33: =-M113*M12 -> -618.18293 | N33: =-N113*N12 -> -618.18293 | O33: =-O113*O12 -> -618.18293 | P33: =-P113*P12 -> -618.18293
D34: Other Income (Expenses) | G34: =Historical!F7 -> 877 | H34: =Historical!G7 -> 1042 | I34: =Historical!H7 -> 2332 | J34: =Historical!I7 -> 1477 | K34: =Historical!J7 -> 1131 | L34: =L24*L13 -> 1934.8495 | M34: =M24*M13 -> 2135.0396 | N34: =N24*N13 -> 2322.807 | O34: =O24*O13 -> 2496.4457 | P34: =P24*P13 -> 2655.0717
D35: Earnings before Tax | G35: =G32+G33+G34 -> 9547 | H35: =H32+H33+H34 -> 12598 | I35: =I32+I33+I34 -> 18421 | J35: =J32+J33+J34 -> 18442 | K35: =K32+K33+K34 -> 13047 | L35: =L32+L33+L34 -> 21536.029 | M35: =M32+M33+M34 -> 24095.256 | N35: =N32+N33+N34 -> 26495.981 | ... P35: =P32+P33+P34 -> 30744.646
D36: Taxes | G36: =-Historical!F28 -> -1810 | H36: =-Historical!G28 -> -1105 | I36: =-Historical!H28 -> -2243 | J36: =-Historical!I28 -> -1640 | K36: =-Historical!J28 -> -2980 | L36: =-L35*L14 -> -3085.6665 | M36: =-M35*M14 -> -3452.3507 | N36: =-N35*N14 -> -3796.3247 | O36: =-O35*O14 -> -4114.4426 | P36: =-P35*P14 -> -4405.0704
D37: Net Earnings | G37: =G35+G36 -> 7737 | H37: =H35+H36 -> 11493 | I37: =I35+I36 -> 16178 | J37: =J35+J36 -> 16802 | K37: =K35+K36 -> 10067 | L37: =L35+L36 -> 18450.363 | M37: =M35+M36 -> 20642.906 | N37: =N35+N36 -> 22699.656 | ... P37: =P35+P36 -> 26339.576
A39: Balance Sheet | F39: Unit | G39: 2019 | H39: 2020 | I39: 2021 | J39: 2022 | K39: 2023 | L39: 2024 | M39: 2025 | N39: 2026 | O39: 2027 | P39: 2028
D40: Assets
D41: Current Assets:
D42: Cash | G42: =Historical!F58 -> 2490.5 | H42: =Historical!G58 -> 1759.4 | I42: =Historical!H58 -> 1742.2 | J42: =Historical!I58 -> 2321.8 | K42: =Historical!J58 -> 2738 | L42: =L95 -> 11097.038 | M42: =M95 -> 20759.467 | N42: =N95 -> 32061.945 | O42: =O95 -> 44935.144 | P42: =P95 -> 59286.395
D43: Bank Deposits | G43: =Historical!F59 -> 4125.5 | H43: =Historical!G59 -> 9162.7 | I43: =Historical!H59 -> 18162.3 | J43: =Historical!I59 -> 23464 | K43: =Historical!J59 -> 23430.9 | L43: =K43 -> 23430.9 | M43: =L43 -> 23430.9 | N43: =M43 -> 23430.9 | O43: =N43 -> 23430.9 | P43: =O43 -> 23430.9
D44: Accounts Receivable | G44: =Historical!F57 -> 12484.1 | H44: =Historical!G57 -> 16493.6 | I44: =Historical!H57 -> 16072.1 | J44: =Historical!I57 -> 18846 | K44: =Historical!J57 -> 21321.8 | L44: =L24*L16/365 -> 23672.211 | M44: =M24*M16/365 -> 26121.467 | N44: =N24*N16/365 -> 28418.737 | O44: =O24*O16/365 -> 30543.145 | P44: =P24*P16/365 -> 32483.879
...

Sheet Scenarios
H3: Scenario | I3: Description | J3: Rate | L3: 2024 | M3: 2025 | N3: 2026 | O3: 2027 | P3: 2028
H4: Base Case | I4: Average growth rate from the past four years | J4: 0.122 | L4: 0.122 | M4: =L4*(1-$J$7) -> 0.1037 | N4: =M4*(1-$J$7) -> 0.088145 | O4: =N4*(1-$J$7) -> 0.07492325 | P4: =O4*(1-$J$7) -> 0.063684762
H5: Bull Case | I5: Maximum growth rate demonstrated by the company | J5: 0.2 | L5: 0.2 | M5: =L5*(1-$J$7) -> 0.17 | N5: =M5*(1-$J$7) -> 0.1445 | O5: =N5*(1-$J$7) -> 0.122825 | P5: =O5*(1-$J$7) -> 0.10440125
H6: Bear Case | I6: Minimum growth rate experienced by the company | J6: 0.062 | L6: 0.062 | M6: =L6*(1-$J$7) -> 0.0527 | N6: =M6*(1-$J$7) -> 0.044795 | O6: =N6*(1-$J$7) -> 0.03807575 | P6: =O6*(1-$J$7) -> 0.032364387
H7: Active Scenario | J7: 0.15

Sheet Comps Valuation
A1: ALKEM LABORATORIES LIMITED
A2: Comps Valuation
E4: Market Data | K4: Financial Data | O4: Valuation
C5: Price | D5: Shares | E5: Market Cap | F5: Debt | G5: Cash & Equivalents | H5: EV | J5: Sales | K5: EBITDA | L5: Earnings | N5: EV/Sales | O5: EV/EBITDA | P5: P/E
A6: Company Name | C6: (₹/Share) | D6: M | E6: ₹ MM | H6: =E6 -> ₹ MM | J6: =H6 -> ₹ MM | K6: =J6 -> ₹ MM | L6: =J6 -> ₹ MM
A7: Dr. Reddy's Laboratories Limited | C7: 6445 | D7: 166.62 | E7: =C7*D7 -> 1073865.9 | F7: 19766.03 | G7: 7502.75 | H7: =E7+F7-G7 -> 1086129.2 | J7: 270140.78 | K7: 80632.4 | L7: 51982.55 | N7: =IFERROR(H7/J7,"") -> 4.0206043 | O7: =IFERROR(H7/K7,"") -> 13.470133 | P7: =IFERROR(E7/L7,"") -> 20.6582
A8: Zydus Lifesciences Limited | C8: 923.25 | D8: 1012.08 | E8: =C8*D8 -> 934402.86 | F8: 1910.79 | G8: 5781.09 | H8: =E8+F8-G8 -> 930532.56 | J8: 187864.45 | K8: 49048.66 | L8: 29610.72 | N8: =IFERROR(H8/J8,"") -> 4.9532126 | O8: =IFERROR(H8/K8,"") -> 18.97162 | P8: =IFERROR(E8/L8,"") -> 31.556236
A9: Torrent Pharmaceuticals Limited | C9: 2627.1 | D9: 338.34 | E9: =C9*D9 -> 888853.01 | F9: 44697.86 | G9: 5129.75 | H9: =E9+F9-G9 -> 928421.12 | J9: 104303.15 | K9: 31025.41 | L9: 14878.34 | N9: =IFERROR(H9/J9,"") -> 8.9011801 | O9: =IFERROR(H9/K9,"") -> 29.92454 | P9: =IFERROR(E9/L9,"") -> 59.74141
A10: Lupin Limited | C10: 2154.05 | D10: 400.95 | E10: =C10*D10 -> 863666.35 | F10: 1786.67 | G10: 3074.85 | H10: =E10+F10-G10 -> 862378.17 | J10: 99037.7 | K10: 23053.59 | L10: 17197.05 | N10: =IFERROR(H10/J10,"") -> 8.7075747 | O10: =IFERROR(H10/K10,"") -> 37.407543 | P10: =IFERROR(E10/L10,"") -> 50.221773
A11: Aurobindo Pharma Limited | C11: 1612.2 | D11: 457.21 | E11: =C11*D11 -> 737113.96 | F11: 37684.11 | G11: 12425.77 | H11: =E11+F11-G11 -> 762372.3 | J11: 193799.04 | K11: 31333.96 | L11: 17833.44 | N11: =IFERROR(H11/J11,"") -> 3.9338291 | O11: =IFERROR(H11/K11,"") -> 24.330544 | P11: =IFERROR(E11/L11,"") -> 41.333246
A12: Abbott India Limited | C12: 1043.8 | D12: 586.5 | E12: =C12*D12 -> 612188.7 | F12: 66201.73 | G12: 44347.15 | H12: =E12+F12-G12 -> 634043.28 | J12: 277103.85 | K12: 48727.42 | L12: 27586.32 | N12: =IFERROR(H12/J12,"") -> 2.2881071 | O12: =IFERROR(H12/K12,"") -> 13.012043 | P12: =IFERROR(E12/L12,"") -> 22.191749
A13: GlaxoSmithKline Pharmaceuticals Limited | C13: 28686.2 | D13: 21.25 | E13: =C13*D13 -> 609581.75 | F13: 911.48 | G13: 2417.65 | H13: =E13+F13-G13 -> 608075.58 | J13: 57287.35 | K13: 13599.67 | L13: 11406.77 | N13: =IFERROR(H13/J13,"") -> 10.614483 | O13: =IFERROR(H13/K13,"") -> 44.712525 | P13: =IFERROR(E13/L13,"") -> 53.440347
A14: Ipca Laboratories Limited | C14: 2169 | D14: 169.37 | E14: =C14*D14 -> 367363.53 | F14: 212.88 | G14: 352.46 | H14: =E14+F14-G14 -> 367223.95 | J14: 32971.9 | K14: 7958.68 | L14: 5266.43 | N14: =IFERROR(H14/J14,"") -> 11.137482 | O14: =IFERROR(H14/K14,"") -> 46.141314 | P14: =IFERROR(E14/L14,"") -> 69.755704
A15: Gland Pharma Limited | C15: 1217.7 | D15: 253.64 | E15: =C15*D15 -> 308857.43 | F15: 19789.53 | G15: 12688 | H15: =E15+F15-G15 -> 315958.96 | J15: 71529.13 | K15: 11088.19 | L15: 5618.65 | N15: =IFERROR(H15/J15,"") -> 4.4172068 | O15: =IFERROR(H15/K15,"") -> 28.495089 | P15: =IFERROR(E15/L15,"") -> 54.970042
C16: 1861.1 | D16: 164.72 | E16: =C16*D16 -> 306560.39 | F16: 3555.02 | G16: 19256 | H16: =E16+F16-G16 -> 290859.41 | J16: 48912.58 | K16: 10292.17 | L16: 6559.04 | N16: =IFERROR(H16/J16,"") -> 5.9465154 | O16: =IFERROR(H16/K16,"") -> 28.260261 | P16: =IFERROR(E16/L16,"") -> 46.738607
A18: Average | N18: =AVERAGE(N7:N16) -> 6.4920195 | O18: =AVERAGE(O7:O16) -> 28.472561 | P18: =AVERAGE(P7:P16) -> 45.060731
A19: Median | N19: =MEDIAN(N7:N16) -> 5.449864 | O19: =MEDIAN(O7:O16) -> 28.377675 | P19: =MEDIAN(P7:P16) -> 48.48019
A21: Alkem Laboratories Limited | C21: 5421 | D21: 120 | E21: =C21*D21 -> 650520 | F21: 14368 | G21: 2762 | H21: 659813 | J21: 125803 | K21: 21840 | L21: 15665 | N21: =IFERROR(H21/J21,"") -> 5.2448113 | O21: =IFERROR(H21/K21,"") -> 30.211218 | P21: =IFERROR(E21/L21,"") -> 41.526971
A23: Metrics | B23: Comps | C23: EV | D23: Net Debt | E23: Equity Value | F23: Shares | G23: Share Price
A24: EV/Revenue | B24: 5.4035 | C24: =B24*J21 -> 679776.51 | D24: -21576 | E24: =C24-D24 -> 701352.51 | F24: 119.57 | G24: =E24/F24 -> 5865.6227
A25: EV/EBITDA | B25: 28.4 | C25: =B25*K21 -> 620256 | D25: -21576 | E25: =C25-D25 -> 641832 | F25: 119.57 | G25: =E25/F25 -> 5367.8347
A26: P/E | B26: 48.4789 | C26: =E26-D26 -> 780997.97 | D26: -21576 | E26: =B26*L21 -> 759421.97 | F26: 119.57 | G26: =E26/F26 -> 6351.2751

Sheet Market Returns
A1: ALKEM LABORATORIES LIMITED
A2: Market Returns
A4: Index Name | B4: Date | C4: Total Returns Index | F4: Nifty 50 TRI
A5: NIFTY 50 | B5: 45323 | C5: 31898.06 | E5: Yearfra | F5: =YEARFRAC(B5,B2476) -> 9.9944444
A6: NIFTY 50 | B6: 45322 | C6: 31939.59
A7: NIFTY 50 | B7: 45321 | C7: 31640.24
A8: NIFTY 50 | B8: 45320 | C8: 31957.05 | E8: Market Returns | F8: 0.151
A9: NIFTY 50 | B9: 45316 | C9: 31391.07
A10: NIFTY 50 | B10: 45315 | C10: 31540.07
A11: NIFTY 50 | B11: 45314 | C11: 31223.3
A12: NIFTY 50 | B12: 45311 | C12: 31712.86
A13: NIFTY 50 | B13: 45310 | C13: 31787.24
A14: NIFTY 50 | B14: 45309 | C14: 31538.4
A15: NIFTY 50 | B15: 45308 | C15: 31699.64
A16: NIFTY 50 | B16: 45307 | C16: 32376.1
A17: NIFTY 50 | B17: 45306 | C17: 32471.8
A18: NIFTY 50 | B18: 45303 | C18: 32173.66
A19: NIFTY 50 | B19: 45302 | C19: 31810.18
A20: NIFTY 50 | B20: 45301 | C20: 31768.3
... A2476: NIFTY 50 | B2476: 41673 | C2476: 7816.09

Sheet Company Beta
A1: ALKEM LABORATORIES LIMITED | G1: Beta | H1: =SLOPE(E7:E66,C7:C66) -> 0.5772212
A2: Company Beta
G3: SUMMARY OUTPUT
B4: Index Close | C4: % Change | D4: Stock | E4: %Change
A5: Date | B5: Price | C5: Monthly | D5: Close Price | E5: Monthly | G5: Regression Statistics
A6: 43497 | B6: 35867.44 | D6: 1746.6 | G6: Multiple R | H6: =CORREL(C7:C66,E7:E66) -> 0.41142623
A7: 43525 | B7: 38672.91 | C7: =B7/B6-1 -> 0.078217737 | D7: 1751.8 | E7: =D7/D6-1 -> 0.0029772129 | G7: R Square | H7: =RSQ(E7:E66,C7:C66) -> 0.16927154
A8: 43556 | B8: 39031.55 | C8: =B8/B7-1 -> 0.009273675 | D8: 1719.95 | E8: =D8/D7-1 -> -0.018181299 | G8: Adjusted R Square | H8: =1-(1-H7)*(60-1)/(60-1-1) -> 0.15494864
A9: 43586 | B9: 39714.2 | C9: =B9/B8-1 -> 0.017489697 | D9: 1790.05 | E9: =D9/D8-1 -> 0.040756999 | G9: Standard Error | H9: =SQRT(INDEX(LINEST(E7:E66,C7:C66,TRUE,TRUE),3,2)/58) -> 0.034667885
A10: 43617 | B10: 39394.64 | C10: =B10/B9-1 -> -0.0080464922 | D10: 1668.65 | E10: =D10/D9-1 -> -0.067819335 | G10: Observations | H10: 60
A11: 43647 | B11: 37481.12 | C11: =B11/B10-1 -> -0.048573105 | D11: 1736.85 | E11: =D11/D10-1 -> 0.040871363
A12: 43678 | B12: 37332.79 | C12: =B12/B11-1 -> -0.0039574591 | D12: 1816.85 | E12: =D12/D11-1 -> 0.046060397 | G12: ANOVA
A13: 43709 | B13: 38667.33 | C13: =B13/B12-1 -> 0.035747127 | D13: 1903.85 | E13: =D13/D12-1 -> 0.047885076 | H13: df | I13: SS | J13: MS | K13: F | L13: Significance F
A14: 43739 | B14: 40129.05 | C14: =B14/B13-1 -> 0.037802455 | D14: 1989.85 | E14: =D14/D13-1 -> 0.045171626 | G14: Regression | H14: 1 | I14: =DEVSQ(E7:E66)-INDEX(LINEST(E7:E66,C7:C66,TRUE,TRUE),5,2) -> 0.057427282 | J14: =I14/H14 -> 0.057427282 | K14: =J14/J15 -> 11.818242 | L14: =_xlfn.F.DIST.RT(K14,H14,H15) -> 0.0010916162
A15: 43770 | B15: 40793.81 | C15: =B15/B14-1 -> 0.016565555 | D15: 2025.2 | E15: =D15/D14-1 -> 0.017765158 | G15: Residual | H15: =60-H14-1 -> 58 | I15: =INDEX(LINEST(E7:E66,C7:C66,TRUE,TRUE),5,2) -> 0.281834 | J15: =I15/H15 -> 0.004859207
A16: 43800 | B16: 41253.74 | C16: =B16/B15-1 -> 0.011274505 | D16: 2013.55 | E16: =D16/D15-1 -> -0.0057525183 | G16: Total | H16: =H14+H15 -> 59 | I16: =I14+I15 -> 0.33926129
A17: 43831 | B17: 40723.49 | C17: =B17/B16-1 -> -0.01285338 | D17: 2394.3 | E17: =D17/D16-1 -> 0.18909389
A18: 43862 | B18: 38297.29 | C18: =B18/B17-1 -> -0.059577409 | D18: 2627.9 | E18: =D18/D17-1 -> 0.09756505 | H18: Coefficients | I18: Standard Error | J18: t Stat | K18: P-value | L18: Lower 95% | M18: Upper 95%
A19: 43891 | B19: 29468.49 | C19: =B19/B18-1 -> -0.23053328 | D19: 2328.85 | E19: =D19/D18-1 -> -0.11379809 | G19: Intercept | H19: =INTERCEPT(E7:E66,C7:C66) -> 0.012947103 | I19: =INDEX(LINEST(E7:E66,C7:C66,TRUE,TRUE),2,2) -> 0.0092718305 | J19: =H19/I19 -> 1.3963913 | K19: =_xlfn.T.DIST.2T(ABS(J19),H15) -> 0.16791808 | L19: =H19-_xlfn.T.INV.2T(0.05,H15)*I19 -> -0.0056124819 | M19: =H19+_xlfn.T.INV.2T(0.05,H15)*I19 -> 0.031506689
A20: 43922 | B20: 33717.62 | C20: =B20/B19-1 -> 0.14419232 | D20: 2608.45 | E20: =D20/D19-1 -> 0.12005926 | G20: X Variable 1 | H20: =SLOPE(E7:E66,C7:C66) -> 0.5772212 | I20: =INDEX(LINEST(E7:E66,C7:C66,TRUE,TRUE),2,1) -> 0.16790586 | J20: =H20/I20 -> 3.4377669 | K20: =_xlfn.T.DIST.2T(ABS(J20),H15) -> 0.0010916162 | L20: =H20-_xlfn.T.INV.2T(0.05,H15)*I20 -> 0.24112111 | M20: =H20+_xlfn.T.INV.2T(0.05,H15)*I20 -> 0.91332129
A21: 43952 | B21: 32424.1 | C21: =B21/B20-1 -> -0.038363325 | D21: 2261.2 | E21: =D21/D20-1 -> -0.13312504
A22: 43983 | B22: 34915.8 | C22: =B22/B21-1 -> 0.07684716 | D22: 2366.1 | E22: =D22/D21-1 -> 0.046391297
A23: 44013 | B23: 37606.89 | C23: =B23/B22-1 -> 0.077073703 | D23: 2662.4 | E23: =D23/D22-1 -> 0.12522717
A24: 44044 | B24: 38628.29 | C24: =B24/B23-1 -> 0.027159917 | D24: 2720.8 | E24: =D24/D23-1 -> 0.021935096
A25: 44075 | B25: 38067.93 | C25: =B25/B24-1 -> -0.014506467 | D25: 2779.05 | E25: =D25/D24-1 -> 0.021409144
A26: 44105 | B26: 39614.07 | C26: =B26/B25-1 -> 0.04061529 | D26: 2634.25 | E26: =D26/D25-1 -> -0.052104136
A27: 44136 | B27: 44149.72 | C27: =B27/B26-1 -> 0.11449594 | D27: 2840.65 | E27: =D27/D26-1 -> 0.078352472
A28: 44166 | B28: 47751.33 | C28: =B28/B27-1 -> 0.081577188 | D28: 2908.7 | E28: =D28/D27-1 -> 0.023955785
A29: 44197 | B29: 46285.77 | C29: =B29/B28-1 -> -0.030691501 | D29: 3003.75 | E29: =D29/D28-1 -> 0.032677829
A30: 44228 | B30: 49099.99 | C30: =B30/B29-1 -> 0.060800976 | D30: 2718.6 | E30: =D30/D29-1 -> -0.094931336
A31: 44256 | B31: 49509.15 | C31: =B31/B30-1 -> 0.0083331993 | D31: 2772.2 | E31: =D31/D30-1 -> 0.01971603
A32: 44287 | B32: 48782.36 | C32: =B32/B31-1 -> -0.014679913 | D32: 2757.25 | E32: =D32/D31-1 -> -0.0053928288
... A66: 45323 | B66: 72500.3 | C66: =B66/B65-1 -> 0.010427429 | D66: 5060.3 | E66: =D66/D65-1 -> 0.013194778

Sheet WACC
A1: ALKEM LABORATORIES LIMITED
A2: Weighted - Average Cost of Capital (WACC)
A3: All Amounts Denominated in INR MM Unless Otherwise Stated
A5: Comparable Companies Beta
E6: Equity & | F6: Total | G6: Debt/ | H6: Debt/ | I6: Tax | J6: Levered | K6: Unlevered
D7: Name | E7: Value | F7: Debt | G7: Equity | H7: Capital | I7: Rate % | J7: Beta | K7: Beta
D8: Dr. Reddy's Laboratories Limited | E8: 6445 | F8: 19766.03 | G8: 19766.03 | H8: 7502.75 | I8: 0.245 | J8: 0.35 | K8: 0.35
D9: Zydus Lifesciences Limited | E9: 923.25 | F9: 1910.79 | G9: 1910.79 | H9: 5781.09 | I9: 0.206 | J9: 0.49 | K9: 0.49
D10: Torrent Pharmaceuticals Limited | E10: 2627.1 | F10: 44697.86 | G10: 44697.86 | H10: 5129.75 | I10: 0.306 | J10: 0.28 | K10: 0.27
D11: Lupin Limited | E11: 2154.05 | F11: 1786.67 | G11: 1786.67 | H11: 3074.85 | I11: 0.202 | J11: 0.66 | K11: 0.66
D12: Aurobindo Pharma Limited | E12: 1612.2 | F12: 37684.11 | G12: 37684.11 | H12: 12425.77 | I12: 0.171 | J12: 0.62 | K12: 0.59
D13: Abbott India Limited | E13: 1043.8 | F13: 66201.73 | G13: 66201.73 | H13: 44347.15 | I13: 0.287 | J13: 0.05 | K13: 0.05
D14: GlaxoSmithKline Pharmaceuticals Limited | E14: 28686.2 | F14: 911.48 | G14: 911.48 | H14: 2417.65 | I14: 0.254 | J14: 0.25 | K14: 0.25
D15: Ipca Laboratories Limited | E15: 2169 | F15: 212.88 | G15: 212.88 | H15: 352.46 | I15: 0.281 | J15: 0.22 | K15: 0.22
D16: Gland Pharma Limited | E16: 1217.7 | F16: 19789.53 | G16: 19789.53 | H16: 12688 | I16: 0.325 | J16: 0.42 | K16: 0.4
E17: 1861.1 | G17: 3555.02 | H17: 19256
D18: Average | G18: =AVERAGE(G8:G16) -> 21440.12 | H18: =AVERAGE(H8:H16) -> 10413.274 | I18: =AVERAGE(I8:I16) -> 0.253 | J18: =AVERAGE(J8:J16) -> 0.37111111 | K18: =AVERAGE(K8:K16) -> 0.36444444
D19: Median | G19: =MEDIAN(G8:G16) -> 19766.03 | H19: =MEDIAN(H8:H16) -> 5781.09 | I19: =MEDIAN(I8:I16) -> 0.254 | J19: =MEDIAN(J8:J16) -> 0.35 | K19: =MEDIAN(K8:K16) -> 0.35
D21: Alkem Pharma | E21: 648207 | F21: 14368
D23: WACC Calculation
D24: Target Capital Structure
D26: Proportion of Debt | K26: =F21/(E21+F21) -> 0.021685092
D27: Proportion of Equity | K27: =E21/(E21+F21) -> 0.97831491
D29: Current Capital Structure
D31: Market Cap | K31: =E21 -> 648207
D32: Total Debt | K32: =F21 -> 14368
D33: Debt / Equity | K33: =F21/E21 -> 0.022165759
D35: Cost of Debt
D36: Pre-Tax Cost of Debt | K36: 0.044
D37: Tax Rate | K37: 0.157
D38: After - Tax Cost of Debt | K38: =K36*(1-K37) -> 0.037092
D40: Cost of Equity
D41: Risk Free Rate | K41: 0.071
D42: Equity market Return | K42: 0.151
D43: Equity Risk Premium | K43: =K42-K41 -> 0.08
D44: Levered Equity Beta | K44: 0.35
D45: Cost of Equity | K45: =K41+K44*K43 -> 0.099
D47: WACC | K47: =K27*K45+K26*K38 -> 0.097657519

Sheet Valuation Summary
A1: ALKEM LABORATORIES LIMITED
A2: Valuation Summary - Football Field
A5: Football Field | H5: Comps | I5: DCF | J5: 52-week hi/lo | K5: Market Consensus | M5: Method | N5: Low | O5: Range
A8: High | H8: 5751 | I8: 5985 | J8: 5193 | K8: 5500 | M8: Comps | N8: 5373 | O8: 378
A9: High | H9: 5751 | I9: 5985 | J9: 5193 | K9: 5500 | M9: DCF | N9: 4350 | O9: 1635
A10: Low | H10: 5373 | I10: 4350 | J10: 3176 | K10: 4800 | M10: 52-week | N10: 3176 | O10: 2017
A11: Low | H11: 5373 | I11: 4350 | J11: 3176 | K11: 4800 | M11: Consensus | N11: 4800 | O11: 700
A13: Valuation Summary
A15: Methodology | B15: Low | C15: High | D15: Midpoint | E15: vs. CMP
A16: DCF | B16: 4350 | C16: 5985 | D16: =AVERAGE(B16:C16) -> 5167.5 | E16: =D16/$B$21-1 -> 0.021245059
A17: Trading Comps | B17: 5373 | C17: 5751 | D17: =AVERAGE(B17:C17) -> 5562 | E17: =D17/$B$21-1 -> 0.099209486
A18: 52-week hi/lo | B18: 3176 | C18: 5193 | D18: =AVERAGE(B18:C18) -> 4184.5 | E18: =D18/$B$21-1 -> -0.17302372
A19: Market Consensus | B19: 4800 | C19: 5500 | D19: =AVERAGE(B19:C19) -> 5150 | E19: =D19/$B$21-1 -> 0.017786561
A20: Blended Target | B20: =MIN(B16:B19) -> 3176 | C20: =MAX(C16:C19) -> 5985 | D20: =AVERAGE(D16:D19) -> 5016 | E20: =D20/B21-1 -> -0.0086956522
A21: Current Market Price | B21: 5060
A22: Recommendation | B22: =IF(E20>0.15,"BUY",IF(E20>0.05,"ACCUMULATE",IF(E20>-0.05,"HOLD",IF(E20>-0.15,"REDUCE","SELL")))) -> HOLD

Sheet Sheet1
