Workbook

Sheet Cover
A1: JPMorgan Chase & Co. Merger & Acquisition Model
A2: Two years of JPM actual data; illustrative target and transaction case
A4: Company | B4: JPMorgan Chase & Co.
A5: Ticker | B5: JPM
A6: Model Date | B6: 46189
A7: Currency / Units | B7: USD $mm except per-share data
A8: Latest Share Price | B8: 319.4
A9: Transaction Structure | B9: Illustrative bank acquisition
A10: Target Company | B10: Illustrative TargetCo
A11: Purchase Price | B11: =Assumptions!B9 -> 65000
A12: % Cash / % Stock | B12: =TEXT(Assumptions!B13,"0%")&" / "&TEXT(Assumptions!B14,"0%") -> 60% / 40%
A13: Pro Forma EPS | B13: ='Accretion Dilution'!E17 -> 24.765419
A14: Standalone Acquirer EPS | B14: ='Accretion Dilution'!E16 -> 23.373075
A15: Accretion / (Dilution) | B15: ='Accretion Dilution'!E18 -> 1.3923435
A16: DCF Implied Target Equity Value | B16: ='DCF Model'!B23 -> 44059.652
A17: Primary Check | B17: PASS

Sheet Assumptions
A1: Assumptions
A2: Editable transaction, financing, synergy, and valuation assumptions
A4: Transaction Assumptions
A5: Acquirer Share Price | B5: 319.4 | C5: $/share
A6: Acquirer Diluted Shares | B6: 2781.5 | C6: mm
A7: Acquirer Standalone Net Income | B7: 57048 | C7: $mm
A8: Target Standalone Net Income | B8: 4500 | C8: $mm
A9: Offer Equity Value | B9: 65000 | C9: $mm
A10: Target Tangible Common Equity | B10: 30000 | C10: $mm
A11: Target Total Assets | B11: 350000 | C11: $mm
A12: Target Total Liabilities | B12: 322000 | C12: $mm
A13: Cash Consideration % | B13: 0.6 | C13: %
A14: Stock Consideration % | B14: 0.4 | C14: %
A15: Deal Fees / Restructuring | B15: 1500 | C15: $mm
A16: Fair Value Mark on Target Loans | B16: -2500 | C16: $mm
A17: Core Deposit Intangible | B17: 3500 | C17: $mm
A18: Goodwill Plug | B18: =B9-B10-B16-B17 -> 34000 | C18: $mm
A19: Financing / Synergy Assumptions
A20: New Debt Raised | B20: 25000 | C20: $mm
A21: Debt Cost | B21: 0.045 | C21: %
A22: Cash Cost of Funds / Lost Interest | B22: 0.035 | C22: %
A23: Pre-tax Cost Synergies | B23: 2500 | C23: $mm
A24: Revenue Synergies | B24: 1000 | C24: $mm
A25: Synergy Realization % | B25: 0.75 | C25: %
A26: Tax Rate | B26: 0.214 | C26: %
A27: Amortization of CDI / Other Intangibles | B27: 350 | C27: $mm
A28: DCF Assumptions
A29: Forecast Revenue CAGR | B29: 0.04 | C29: %
A30: Forecast Net Income Margin | B30: 0.25 | C30: % of revenue
A31: Payout Ratio | B31: 0.35 | C31: %
A32: Discount Rate / Cost of Equity | B32: 0.105 | C32: %
A33: Terminal Growth | B33: 0.025 | C33: %
A34: Terminal P/E Multiple | B34: 11 | C34: x
A35: Sensitivity Low / High | B35: -0.1 | C35: delta
A36: Model Note | B36: TargetCo values are illustrative placeholders pending user-provided target. | C36: text

Sheet Acquirer Co Model
A1: Acquirer Co Model
A2: JPMorgan Chase historical statements and simple forecast
A4: Income Statement | B4: FY2024A | C4: FY2025A | D4: FY2026E | E4: FY2027E
A5: Investment banking fees | B5: 8910 | C5: 9615 | D5: =C5*(1+Assumptions!$B$29) -> 9999.6 | E5: =D5*(1+Assumptions!$B$29) -> 10399.584
A6: Principal transactions | B6: 24787 | C6: 27212 | D6: =C6*(1+Assumptions!$B$29) -> 28300.48 | E6: =D6*(1+Assumptions!$B$29) -> 29432.499
A7: Lending- and deposit-related fees | B7: 7606 | C7: 9093 | D7: =C7*(1+Assumptions!$B$29) -> 9456.72 | E7: =D7*(1+Assumptions!$B$29) -> 9834.9888
A8: Asset management fees | B8: 17801 | C8: 20327 | D8: =C8*(1+Assumptions!$B$29) -> 21140.08 | E8: =D8*(1+Assumptions!$B$29) -> 21985.683
A9: Commissions and other fees | B9: 7530 | C9: 8539 | D9: =C9*(1+Assumptions!$B$29) -> 8880.56 | E9: =D9*(1+Assumptions!$B$29) -> 9235.7824
A10: Investment securities gains/(losses) | B10: -1021 | C10: -57 | D10: =C10*(1+Assumptions!$B$29) -> -59.28 | E10: =D10*(1+Assumptions!$B$29) -> -61.6512
A11: Mortgage fees and related income | B11: 1401 | C11: 1381 | D11: =C11*(1+Assumptions!$B$29) -> 1436.24 | E11: =D11*(1+Assumptions!$B$29) -> 1493.6896
A12: Card income | B12: 5497 | C12: 4720 | D12: =C12*(1+Assumptions!$B$29) -> 4908.8 | E12: =D12*(1+Assumptions!$B$29) -> 5105.152
A13: Other income | B13: 12462 | C13: 6174 | D13: =C13*(1+Assumptions!$B$29) -> 6420.96 | E13: =D13*(1+Assumptions!$B$29) -> 6677.7984
A14: Noninterest revenue | B14: 84973 | C14: 87004 | D14: =C14*(1+Assumptions!$B$29) -> 90484.16 | E14: =D14*(1+Assumptions!$B$29) -> 94103.526
A15: Net interest income | B15: 92583 | C15: 95443 | D15: =C15*(1+Assumptions!$B$29) -> 99260.72 | E15: =D15*(1+Assumptions!$B$29) -> 103231.15
A16: Total net revenue | B16: 177556 | C16: 182447 | D16: =C16*(1+Assumptions!$B$29) -> 189744.88 | E16: =D16*(1+Assumptions!$B$29) -> 197334.68
... A18: Noninterest expense | B18: 91797 | C18: 95640 | D18: =C18*(1+Assumptions!$B$29) -> 99465.6 | E18: =D18*(1+Assumptions!$B$29) -> 103444.22
A19: Income before tax | B19: =B16-B17-B18 -> 75081 | C19: =C16-C17-C18 -> 72595 | D19: =D16-D17-D18 -> 75498.8 | E19: =E16-E17-E18 -> 78518.752
A20: Income tax expense | B20: =B19*Assumptions!$B$26 -> 16067.334 | C20: =C19*Assumptions!$B$26 -> 15535.33 | D20: =D19*Assumptions!$B$26 -> 16156.743 | E20: =E19*Assumptions!$B$26 -> 16803.013
A21: Net income | B21: =B19-B20 -> 59013.666 | C21: =C19-C20 -> 57059.67 | D21: =D19-D20 -> 59342.057 | E21: =E19-E20 -> 61715.739
A22: Net income to common | B22: 56868 | C22: 55681 | D22: =D21-1367 -> 57975.057 | E22: =E21-1367 -> 60348.739
A23: Diluted shares | B23: 2879 | C23: 2781.5 | D23: =C23*(1-1.5%) -> 2739.7775 | E23: =D23*(1-1%) -> 2712.3797
A24: Diluted EPS | B24: =B22/B23 -> 19.752692 | C24: =C22/C23 -> 20.018335 | D24: =D22/D23 -> 21.160498 | E24: =E22/E23 -> 22.24937
A27: Balance Sheet | B27: FY2024A | C27: FY2025A | D27: FY2026E | E27: FY2027E
A28: Cash and due from banks | B28: 23372 | C28: 21742 | D28: =C28*(1+2.5%) -> 22285.55 | E28: =D28*(1+2.5%) -> 22842.689
A29: Deposits with banks | B29: 445945 | C29: 321596 | D29: =C29*(1+2.5%) -> 329635.9 | E29: =D29*(1+2.5%) -> 337876.8
A30: Fed funds sold / resale agreements | B30: 295001 | C30: 336426 | D30: =C30*(1+2.5%) -> 344836.65 | E30: =D30*(1+2.5%) -> 353457.57
A31: Securities borrowed | B31: 219546 | C31: 286191 | D31: =C31*(1+2.5%) -> 293345.77 | E31: =D31*(1+2.5%) -> 300679.42
A32: Trading assets | B32: 637784 | C32: 802873 | D32: =C32*(1+2.5%) -> 822944.82 | E32: =D32*(1+2.5%) -> 843518.45
A33: Investment securities | B33: 681320 | C33: 777332 | D33: =C33*(1+2.5%) -> 796765.3 | E33: =D33*(1+2.5%) -> 816684.43
A34: Loans, net | B34: 1323643 | C34: 1467664 | D34: =C34*(1+2.5%) -> 1504355.6 | E34: =D34*(1+2.5%) -> 1541964.5
A35: Accrued interest / receivables | B35: 101223 | C35: 111599 | D35: =C35*(1+2.5%) -> 114388.97 | E35: =D35*(1+2.5%) -> 117248.7
A36: Premises and equipment | B36: 32223 | C36: 36244 | D36: =C36*(1+2.5%) -> 37150.1 | E36: =D36*(1+2.5%) -> 38078.852
A37: Goodwill, MSRs and intangibles | B37: 64560 | C37: 64458 | D37: =C37*(1+2.5%) -> 66069.45 | E37: =D37*(1+2.5%) -> 67721.186
A38: Other assets | B38: 178197 | C38: 198775 | D38: =C38*(1+2.5%) -> 203744.37 | E38: =D38*(1+2.5%) -> 208837.98
A39: Total assets | B39: 4002814 | C39: 4424900 | D39: =C39*(1+2.5%) -> 4535522.5 | E39: =D39*(1+2.5%) -> 4648910.6
... A46: Total liabilities | B46: 3658056 | C46: 4062462 | D46: =C46*(1+2.5%) -> 4164023.5 | E46: =D46*(1+2.5%) -> 4268124.1
A47: Total stockholders equity | B47: 344758 | C47: 362438 | D47: =C47*(1+3%) -> 373311.14 | E47: =D47*(1+3%) -> 384510.47
A48: Total liabilities + equity | B48: =B46+B47 -> 4002814 | C48: =C46+C47 -> 4424900 | D48: =D46+D47 -> 4537334.7 | E48: =E46+E47 -> 4652634.6
A49: Balance check | B49: =B39-B48 -> 0 | C49: =C39-C48 -> 0 | D49: =D39-D48 -> -1812.19 | E49: =E39-E48 -> -3724.0504
A52: Cash Flow Statement | B52: FY2024A | C52: FY2025A | D52: FY2026E | E52: FY2027E
...

Sheet Target Model
A1: Target Model
A2: Illustrative TargetCo two-year data, forecast, and standalone valuation support
A4: TargetCo Income Statement | B4: FY2024A | C4: FY2025A | D4: FY2026E | E4: FY2027E | F4: FY2028E
A5: Revenue / Net revenue | B5: 17000 | C5: 18000 | D5: =C5*(1+Assumptions!$B$29) -> 18720 | E5: =D5*(1+Assumptions!$B$29) -> 19468.8 | F5: =E5*(1+Assumptions!$B$29) -> 20247.552
A6: Revenue growth | C6: 0.0588 | D6: =D5/C5-1 -> 0.04 | E6: =E5/D5-1 -> 0.04 | F6: =F5/E5-1 -> 0.04
A7: Provision for credit losses | B7: 1200 | C7: 1300 | D7: =C7/C5*D5 -> 1352 | E7: =D7/D5*E5 -> 1406.08 | F7: =E7/E5*F5 -> 1462.3232
A8: Noninterest expense | B8: 9800 | C8: 10000 | D8: =C8/C5*D5 -> 10400 | E8: =D8/D5*E5 -> 10816 | F8: =E8/E5*F5 -> 11248.64
A9: Pre-tax income | B9: 6000 | C9: 6700 | D9: =D5-D7-D8 -> 6968 | E9: =E5-E7-E8 -> 7246.72 | F9: =F5-F7-F8 -> 7536.5888
A10: Tax expense | B10: 1300 | C10: 1434 | D10: =D9*Assumptions!$B$26 -> 1491.152 | E10: =E9*Assumptions!$B$26 -> 1550.7981 | F10: =F9*Assumptions!$B$26 -> 1612.83
A11: Net income | B11: 4700 | C11: 5266 | D11: =D9-D10 -> 5476.848 | E11: =E9-E10 -> 5695.9219 | F11: =F9-F10 -> 5923.7588
A12: Dividends | B12: 1600 | C12: 1800 | D12: =D11*Assumptions!$B$31 -> 1916.8968 | E12: =E11*Assumptions!$B$31 -> 1993.5727 | F12: =F11*Assumptions!$B$31 -> 2073.3156
A13: Retained earnings contribution | B13: 3100 | C13: 3466 | D13: =D11-D12 -> 3559.9512 | E13: =E11-E12 -> 3702.3492 | F13: =F11-F12 -> 3850.4432
A14: Diluted shares | B14: 500 | C14: 500 | D14: =C14 -> 500 | E14: =D14 -> 500 | F14: =E14 -> 500
A15: Diluted EPS | B15: 9.4 | C15: 10.53 | D15: =D11/D14 -> 10.953696 | E15: =E11/E14 -> 11.391844 | F15: =F11/F14 -> 11.847518
A18: TargetCo Balance Sheet | B18: FY2024A | C18: FY2025A | D18: FY2026E | E18: FY2027E | F18: FY2028E
A19: Cash | B19: 15000 | C19: 16000 | D19: =C19*(1+2%) -> 16320 | E19: =D19*(1+2%) -> 16646.4 | F19: =E19*(1+2%) -> 16979.328
A20: Loans / earning assets | B20: 300000 | C20: 315000 | D20: =C20*(1+4%) -> 327600 | E20: =D20*(1+4%) -> 340704 | F20: =E20*(1+4%) -> 354332.16
A21: Other assets | B21: 28000 | C21: 29000 | D21: =C21*(1+3%) -> 29870 | E21: =D21*(1+3%) -> 30766.1 | F21: =E21*(1+3%) -> 31689.083
A22: Total assets | B22: 343000 | C22: 360000 | D22: =SUM(D19:D21) -> 373790 | E22: =SUM(E19:E21) -> 388116.5 | F22: =SUM(F19:F21) -> 403000.57
A23: Deposits / funding liabilities | B23: 275000 | C23: 288000 | D23: =D22*80% -> 299032 | E23: =E22*80% -> 310493.2 | F23: =F22*80% -> 322400.46
A24: Debt | B24: 33000 | C24: 34000 | D24: =C24*(1+2%) -> 34680 | E24: =D24*(1+2%) -> 35373.6 | F24: =E24*(1+2%) -> 36081.072
A25: Other liabilities | B25: 7000 | C25: 8000 | D25: =D22-D23-D24-D26 -> 0 | E25: =E22-E23-E24-E26 -> 0 | F25: =F22-F23-F24-F26 -> 0
A26: Total liabilities | B26: 315000 | C26: 330000 | D26: =SUM(D23:D25) -> 0 | E26: =SUM(E23:E25) -> 0 | F26: =SUM(F23:F25) -> 0
A27: Stockholders equity | B27: 28000 | C27: 30000 | D27: =C26+D13 -> 333559.95 | E27: =D26+E13 -> 0 | F27: =E26+F13 -> 0
A28: Liabilities + equity | B28: 343000 | C28: 360000 | D28: =D26+D27 -> 0 | E28: =E26+E27 -> 0 | F28: =F26+F27 -> 0
A29: Balance check | B29: 0 | C29: 0 | D29: =D22-D28 -> 0 | E29: =E22-E28 -> 0 | F29: =F22-F28 -> 0
A32: TargetCo Cash Flow | B32: FY2024A | C32: FY2025A | D32: FY2026E | E32: FY2027E | F32: FY2028E
A33: Net income | B33: 4700 | C33: 5266 | D33: =D11 -> 5476.848 | E33: =E11 -> 5695.9219 | F33: =F11 -> 5923.7588
A34: D&A / non-cash items | B34: 350 | C34: 375 | D34: =C34*(1+3%) -> 386.25 | E34: =D34*(1+3%) -> 397.8375 | F34: =E34*(1+3%) -> 409.77263
A35: Change in balance sheet / working capital | B35: -800 | C35: -900 | D35: =-D5*5% -> -936 | E35: =-E5*5% -> -973.44 | F35: =-F5*5% -> -1012.3776
A36: Net cash from operations | B36: 4250 | C36: 4741 | D36: =SUM(D33:D35) -> 4927.098 | E36: =SUM(E33:E35) -> 5120.3194 | F36: =SUM(F33:F35) -> 5321.1538
A37: Investing / loan growth | B37: -6000 | C37: -7000 | D37: =-(D20-C20) -> -12600 | E37: =-(E20-D20) -> -13104 | F37: =-(F20-E20) -> -13628.16
A38: Financing / dividends | B38: 2500 | C38: 3000 | D38: =D12 -> 1916.8968 | E38: =E12 -> 1993.5727 | F38: =F12 -> 2073.3156
A39: Net change in cash | B39: 750 | C39: 741 | D39: =SUM(D36:D38) -> -5756.0052 | E39: =SUM(E36:E38) -> -5990.1079 | F39: =SUM(F36:F38) -> -6233.6906

Sheet Support Schedules
A1: Support Schedules
A2: Financing, synergy realization, and purchase accounting support
A4: Financing Schedule | B4: FY2025 Close | C4: FY2026E | D4: FY2027E | E4: FY2028E
A5: Purchase price | B5: =Assumptions!B9 -> 65000 | C5: =B5 -> 65000 | D5: =B5 -> 65000 | E5: =B5 -> 65000
A6: Cash consideration | B6: =B5*Assumptions!B13 -> 39000 | C6: =B6 -> 39000 | D6: =B6 -> 39000 | E6: =B6 -> 39000
A7: Stock consideration | B7: =B5*Assumptions!B14 -> 26000 | C7: =B7 -> 26000 | D7: =B7 -> 26000 | E7: =B7 -> 26000
A8: New debt raised | B8: =Assumptions!B20 -> 25000 | C8: =B8 -> 25000 | D8: =B8 -> 25000 | E8: =B8 -> 25000
A9: New shares issued | B9: =B7/Assumptions!B5 -> 81.40263 | C9: =B9 -> 81.40263 | D9: =B9 -> 81.40263 | E9: =B9 -> 81.40263
A10: Annual interest expense | B10: =B8*Assumptions!B21 -> 1125 | C10: =C8*Assumptions!B21 -> 1125 | D10: =D8*Assumptions!B21 -> 1125 | E10: =E8*Assumptions!B21 -> 1125
A11: After-tax interest expense | B11: =B10*(1-Assumptions!B26) -> 884.25 | C11: =C10*(1-Assumptions!B26) -> 884.25 | D11: =D10*(1-Assumptions!B26) -> 884.25 | E11: =E10*(1-Assumptions!B26) -> 884.25
A12: Lost interest on cash | B12: =B6*Assumptions!B22 -> 1365 | C12: =C6*Assumptions!B22 -> 1365 | D12: =D6*Assumptions!B22 -> 1365 | E12: =E6*Assumptions!B22 -> 1365
A13: After-tax lost interest | B13: =B12*(1-Assumptions!B26) -> 1072.89 | C13: =C12*(1-Assumptions!B26) -> 1072.89 | D13: =D12*(1-Assumptions!B26) -> 1072.89 | E13: =E12*(1-Assumptions!B26) -> 1072.89
A16: Synergy Schedule | B16: FY2025 Close | C16: FY2026E | D16: FY2027E | E16: FY2028E
A17: Gross cost synergies | B17: =Assumptions!B23 -> 2500 | C17: =B17 -> 2500 | D17: =B17 -> 2500 | E17: =B17 -> 2500
A18: Revenue synergies | B18: =Assumptions!B24 -> 1000 | C18: =B18 -> 1000 | D18: =B18 -> 1000 | E18: =B18 -> 1000
A19: Realized % | B19: =Assumptions!B25 -> 0.75 | C19: =B19 -> 0.75 | D19: =B19 -> 0.75 | E19: =B19 -> 0.75
A20: Pre-tax realized synergies | B20: =(B17+B18)*B19 -> 2625 | C20: =(C17+C18)*C19 -> 2625 | D20: =(D17+D18)*D19 -> 2625 | E20: =(E17+E18)*E19 -> 2625
A21: After-tax synergies | B21: =B20*(1-Assumptions!B26) -> 2063.25 | C21: =C20*(1-Assumptions!B26) -> 2063.25 | D21: =D20*(1-Assumptions!B26) -> 2063.25 | E21: =E20*(1-Assumptions!B26) -> 2063.25
A22: Intangible amortization | B22: =Assumptions!B27 -> 350 | C22: =B22 -> 350 | D22: =B22 -> 350 | E22: =B22 -> 350
A23: After-tax amortization | B23: =B22*(1-Assumptions!B26) -> 275.1 | C23: =C22*(1-Assumptions!B26) -> 275.1 | D23: =D22*(1-Assumptions!B26) -> 275.1 | E23: =E22*(1-Assumptions!B26) -> 275.1
A26: Purchase Accounting | B26: FY2025 Close
A27: Purchase price | B27: =Assumptions!B9 -> 65000
A28: Target tangible common equity | B28: =Assumptions!B10 -> 30000
A29: Fair value mark | B29: =Assumptions!B16 -> -2500
A30: Core deposit intangible | B30: =Assumptions!B17 -> 3500
A31: Deal fees / restructuring | B31: =Assumptions!B15 -> 1500
A32: Goodwill created | B32: =B27-B28-B29-B30 -> 34000
A33: Total accounting adjustments | B33: =SUM(B29:B32) -> 36500
A34: Cash paid | B34: =B27*Assumptions!B13 -> 39000
A35: Stock issued | B35: =B27*Assumptions!B14 -> 26000

Sheet DCF Model
A1: DCF Model
A2: TargetCo standalone dividend-discount / equity value proxy
A4: DCF / Equity Value | B4: FY2026E | C4: FY2027E | D4: FY2028E | E4: FY2029E | F4: FY2030E
A5: Revenue | B5: ='Target Model'!D5 -> 18720 | C5: ='Target Model'!E5 -> 19468.8 | D5: ='Target Model'!F5 -> 20247.552 | E5: =D5*(1+Assumptions!$B$29) -> 21057.454 | F5: =E5*(1+Assumptions!$B$29) -> 21899.752
A6: Revenue growth | B6: =B5/'Target Model'!C5-1 -> 0.04 | C6: =C5/B5-1 -> 0.04 | D6: =D5/C5-1 -> 0.04 | E6: =E5/D5-1 -> 0.04 | F6: =F5/E5-1 -> 0.04
A7: Net income margin | B7: =Assumptions!$B$30 -> 0.25 | C7: =Assumptions!$B$30 -> 0.25 | D7: =Assumptions!$B$30 -> 0.25 | E7: =Assumptions!$B$30 -> 0.25 | F7: =Assumptions!$B$30 -> 0.25
A8: Net income | B8: =B5*B7 -> 4680 | C8: =C5*C7 -> 4867.2 | D8: =D5*D7 -> 5061.888 | E8: =E5*E7 -> 5264.3635 | F8: =F5*F7 -> 5474.9381
A9: Payout ratio | B9: =Assumptions!$B$31 -> 0.35 | C9: =Assumptions!$B$31 -> 0.35 | D9: =Assumptions!$B$31 -> 0.35 | E9: =Assumptions!$B$31 -> 0.35 | F9: =Assumptions!$B$31 -> 0.35
A10: Distributable earnings / dividends | B10: =B8*B9 -> 1638 | C10: =C8*C9 -> 1703.52 | D10: =D8*D9 -> 1771.6608 | E10: =E8*E9 -> 1842.5272 | F10: =F8*F9 -> 1916.2283
A11: Terminal net income | F11: =F8*(1+Assumptions!$B$33) -> 5611.8115
A12: Terminal value @ P/E | F12: =F11*Assumptions!$B$34 -> 61729.927
A13: PV factor | B13: =1/(1+Assumptions!$B$32)^1 -> 0.90497738 | C13: =1/(1+Assumptions!$B$32)^2 -> 0.81898405 | D13: =1/(1+Assumptions!$B$32)^3 -> 0.74116204 | E13: =1/(1+Assumptions!$B$32)^4 -> 0.67073487 | F13: =1/(1+Assumptions!$B$32)^5 -> 0.60699989
A14: PV of dividends | B14: =B10*B13 -> 1482.3529 | C14: =C10*C13 -> 1395.1557 | D14: =D10*D13 -> 1313.0877 | E14: =E10*E13 -> 1235.8473 | F14: =F10*F13 -> 1163.1504
A15: PV of terminal value | F15: =F12*F13 -> 37470.058
A16: Implied equity value | B16: =SUM(B14:F14)+F15 -> 44059.652
A17: Less: illustrative transaction price | B17: =Assumptions!B9 -> 65000
A20: Implied equity value | B20: =B16 -> 44059.652
A21: Offer equity value | B21: =Assumptions!B9 -> 65000
A22: Premium / (Discount) | B22: =B20/B21-1 -> -0.32215919
A23: DCF Implied Target Equity Value | B23: =B20 -> 44059.652
A24: Terminal P/E | B24: =Assumptions!B34 -> 11
A25: Discount Rate | B25: =Assumptions!B32 -> 0.105

Sheet Closing Balance Sheet
A1: Closing Balance Sheet
A2: Sources & Uses and pro forma opening balance sheet
A4: Sources & Uses | B4: Acquirer | C4: Target | D4: Adjustments | E4: Pro Forma
A5: Existing cash funding | D5: ='Support Schedules'!B6+Assumptions!B15-'Support Schedules'!B8 -> 15500 | E5: =D5 -> 15500
A6: Stock consideration | D6: ='Support Schedules'!B7 -> 26000 | E6: =D6 -> 26000
A7: New debt financing | D7: ='Support Schedules'!B8 -> 25000 | E7: =D7 -> 25000
A8: Other funding | D8: =0 -> 0 | E8: =D8 -> 0
A9: Total sources | D9: =SUM(D5:D8) -> 66500 | E9: =D9 -> 66500
A10: Purchase equity value | D10: =Assumptions!B9 -> 65000 | E10: =D10 -> 65000
A11: Repay/refinance target debt | D11: =0 -> 0 | E11: =D11 -> 0
A12: Deal fees / restructuring | D12: =Assumptions!B15 -> 1500 | E12: =D12 -> 1500
A13: Total uses | D13: =SUM(D10:D12) -> 66500 | E13: =D13 -> 66500
A14: Sources - Uses check | D14: =D9-D13 -> 0 | E14: =D14 -> 0
A17: Opening Balance Sheet | B17: Acquirer FY2025A | C17: Target FY2025A | D17: Transaction Adj. | E17: Pro Forma Close
A18: Cash / deposits with banks | B18: =SUM('Acquirer Co Model'!C28:C29) -> 343338 | C18: ='Target Model'!C19 -> 16000 | D18: =-D5 -> -15500 | E18: =SUM(B18:D18) -> 343838
A19: Loans / earning assets | B19: ='Acquirer Co Model'!C34 -> 1467664 | C19: ='Target Model'!C20 -> 315000 | D19: =Assumptions!B16 -> -2500 | E19: =SUM(B19:D19) -> 1780164
A20: Trading and investment assets | B20: =SUM('Acquirer Co Model'!C30:C33) -> 2202822 | D20: =0 -> 0 | E20: =SUM(B20:D20) -> 2202822
A21: Goodwill and intangibles | B21: ='Acquirer Co Model'!C37 -> 64458 | C21: =0 -> 0 | D21: ='Support Schedules'!B32+Assumptions!B17 -> 37500 | E21: =SUM(B21:D21) -> 101958
A22: Other assets | B22: =SUM('Acquirer Co Model'!C35:C36)+'Acquirer Co Model'!C38 -> 346618 | C22: ='Target Model'!C21 -> 29000 | D22: =0 -> 0 | E22: =SUM(B22:D22) -> 375618
A23: Total assets | B23: =SUM(B18:B22) -> 4424900 | C23: ='Target Model'!C22 -> 360000 | D23: =SUM(D18:D22) -> 19500 | E23: =SUM(E18:E22) -> 4804400
A24: Deposits | B24: ='Acquirer Co Model'!C40 -> 2559320 | C24: ='Target Model'!C23 -> 288000 | D24: =0 -> 0 | E24: =SUM(B24:D24) -> 2847320
A25: Borrowings / debt | B25: =SUM('Acquirer Co Model'!C41:C42,'Acquirer Co Model'!C45) -> 942378 | C25: ='Target Model'!C24 -> 34000 | D25: ='Support Schedules'!B8 -> 25000 | E25: =SUM(B25:D25) -> 1001378
A26: Other liabilities | B26: ='Acquirer Co Model'!C46-B24-B25 -> 560764 | C26: ='Target Model'!C25 -> 8000 | D26: =0 -> 0 | E26: =SUM(B26:D26) -> 568764
A27: Total liabilities | B27: =SUM(B24:B26) -> 4062462 | C27: ='Target Model'!C26 -> 330000 | D27: =SUM(D24:D26) -> 25000 | E27: =SUM(E24:E26) -> 4417462
A28: Preferred equity | B28: ='Acquirer Co Model'!C47*5.5% -> 19934.09 | C28: =0 -> 0 | D28: =0 -> 0 | E28: =SUM(B28:D28) -> 19934.09
A29: Common equity / APIC | B29: ='Acquirer Co Model'!C47*26.2% -> 94958.756 | C29: =0 -> 0 | D29: ='Support Schedules'!B35 -> 26000 | E29: =SUM(B29:D29) -> 120958.76
A30: Retained earnings / AOCI / Treasury | B30: ='Acquirer Co Model'!C47*68.3% -> 247545.15 | C30: ='Target Model'!C27 -> 30000 | D30: =-'Target Model'!C27-Assumptions!B15 -> -31500 | E30: =SUM(B30:D30) -> 246045.15
A31: Total equity | B31: =SUM(B28:B30) -> 362438 | C31: ='Target Model'!C27 -> 30000 | D31: =SUM(D28:D30) -> -5500 | E31: =SUM(E28:E30) -> 386938
A32: Balance check | B32: =B23-B27-B31 -> 0 | C32: =C23-C27-C31 -> 0 | D32: =D23-D27-D31 -> 0 | E32: =E23-E27-E31 -> 0

Sheet Pro Forma Model
A1: Pro Forma Model
A2: Pro forma combined income statement, balance sheet, and cash flow
A4: Pro Forma Income Statement | B4: FY2025A / Close | C4: FY2026E | D4: FY2027E | E4: FY2028E | F4: Notes
A5: Acquirer net revenue | B5: ='Acquirer Co Model'!C16 -> 182447 | C5: ='Acquirer Co Model'!D16 -> 189744.88 | D5: ='Acquirer Co Model'!E16 -> 197334.68 | E5: ='Acquirer Co Model'!E16*(1+Assumptions!$B$29) -> 205228.06
A6: Target revenue | B6: ='Target Model'!C5 -> 18000 | C6: ='Target Model'!D5 -> 18720 | D6: ='Target Model'!E5 -> 19468.8 | E6: ='Target Model'!F5 -> 20247.552
A7: Revenue synergies | B7: ='Support Schedules'!B18*'Support Schedules'!B19 -> 750 | C7: ='Support Schedules'!C18*'Support Schedules'!C19 -> 750 | D7: ='Support Schedules'!D18*'Support Schedules'!D19 -> 750 | E7: ='Support Schedules'!E18*'Support Schedules'!E19 -> 750
A8: Combined net revenue | B8: =SUM(B5:B7) -> 201197 | C8: =SUM(C5:C7) -> 209214.88 | D8: =SUM(D5:D7) -> 217553.48 | E8: =SUM(E5:E7) -> 226225.61
A9: Acquirer pre-tax income | B9: ='Acquirer Co Model'!C19 -> 72595 | C9: ='Acquirer Co Model'!D19 -> 75498.8 | D9: ='Acquirer Co Model'!E19 -> 78518.752 | E9: ='Acquirer Co Model'!E19*(1+Assumptions!$B$29) -> 81659.502
A10: Target pre-tax income | B10: ='Target Model'!C9 -> 6700 | C10: ='Target Model'!D9 -> 6968 | D10: ='Target Model'!E9 -> 7246.72 | E10: ='Target Model'!F9 -> 7536.5888
A11: Cost / revenue synergies | B11: ='Support Schedules'!B20 -> 2625 | C11: ='Support Schedules'!C20 -> 2625 | D11: ='Support Schedules'!D20 -> 2625 | E11: ='Support Schedules'!E20 -> 2625
A12: Interest expense on debt | B12: =-'Support Schedules'!B10 -> -1125 | C12: =-'Support Schedules'!C10 -> -1125 | D12: =-'Support Schedules'!D10 -> -1125 | E12: =-'Support Schedules'!E10 -> -1125
A13: Lost interest on cash | B13: =-'Support Schedules'!B12 -> -1365 | C13: =-'Support Schedules'!C12 -> -1365 | D13: =-'Support Schedules'!D12 -> -1365 | E13: =-'Support Schedules'!E12 -> -1365
A14: Intangible amortization | B14: =-'Support Schedules'!B22 -> -350 | C14: =-'Support Schedules'!C22 -> -350 | D14: =-'Support Schedules'!D22 -> -350 | E14: =-'Support Schedules'!E22 -> -350
A15: Pro forma pre-tax income | B15: =SUM(B9:B14) -> 79080 | C15: =SUM(C9:C14) -> 82251.8 | D15: =SUM(D9:D14) -> 85550.472 | E15: =SUM(E9:E14) -> 88981.091
A16: Tax expense | B16: =B15*Assumptions!$B$26 -> 16923.12 | C16: =C15*Assumptions!$B$26 -> 17601.885 | D16: =D15*Assumptions!$B$26 -> 18307.801 | E16: =E15*Assumptions!$B$26 -> 19041.953
A17: Pro forma net income | B17: =B15-B16 -> 62156.88 | C17: =C15-C16 -> 64649.915 | D17: =D15-D16 -> 67242.671 | E17: =E15-E16 -> 69939.137
A18: Preferred dividends | B18: =1367 -> 1367 | C18: =B18 -> 1367 | D18: =B18 -> 1367 | E18: =B18 -> 1367
A19: Pro forma common net income | B19: =B17-B18 -> 60789.88 | C19: =C17-C18 -> 63282.915 | D19: =D17-D18 -> 65875.671 | E19: =E17-E18 -> 68572.137
A22: Pro Forma Balance Sheet | B22: Close | C22: FY2026E | D22: FY2027E | E22: FY2028E | F22: Notes
A23: Total assets | B23: ='Closing Balance Sheet'!E23 -> 4804400 | C23: =B23*(1+3%) -> 4948532 | D23: =C23*(1+3%) -> 5096988 | E23: =D23*(1+3%) -> 5249897.6
A24: Total liabilities | B24: ='Closing Balance Sheet'!E27 -> 4417462 | C24: =B24*(1+3%) -> 4549985.9 | D24: =C24*(1+3%) -> 4686485.4 | E24: =D24*(1+3%) -> 4827080
A25: Total equity | B25: =B23-B24 -> 386938 | C25: =C23-C24 -> 398546.14 | D25: =D23-D24 -> 410502.52 | E25: =E23-E24 -> 422817.6
A26: Balance check | B26: =B23-B24-B25 -> 0 | C26: =C23-C24-C25 -> 0 | D26: =D23-D24-D25 -> 0 | E26: =E23-E24-E25 -> 0
A27: Deposits | B27: ='Closing Balance Sheet'!E24 -> 2847320 | C27: =B27*(1+3%) -> 2932739.6 | D27: =C27*(1+3%) -> 3020721.8 | E27: =D27*(1+3%) -> 3111343.4
A28: Borrowings / debt | B28: ='Closing Balance Sheet'!E25 -> 1001378 | C28: =B28*(1+2%) -> 1021405.6 | D28: =C28*(1+2%) -> 1041833.7 | E28: =D28*(1+2%) -> 1062670.3
A29: Goodwill / intangibles | B29: ='Closing Balance Sheet'!E21 -> 101958 | C29: =B29-Assumptions!B29 -> 101957.96 | D29: =C29-Assumptions!B29 -> 101957.92 | E29: =D29-Assumptions!B29 -> 101957.88
A30: Loans / earning assets | B30: ='Closing Balance Sheet'!E19 -> 1780164 | C30: =B30*(1+4%) -> 1851370.6 | D30: =C30*(1+4%) -> 1925425.4 | E30: =D30*(1+4%) -> 2002442.4
A31: Cash / deposits with banks | B31: ='Closing Balance Sheet'!E18 -> 343838 | C31: =B31*(1+1%) -> 347276.38 | D31: =C31*(1+1%) -> 350749.14 | E31: =D31*(1+1%) -> 354256.64
A32: Tangible common equity proxy | B32: =B25-B29 -> 284980 | C32: =C25-C29 -> 296588.18 | D32: =D25-D29 -> 308544.6 | E32: =E25-E29 -> 320859.72
A35: Pro Forma Cash Flow | B35: Close | C35: FY2026E | D35: FY2027E | E35: FY2028E | F35: Notes
A36: Pro forma net income | B36: =B17 -> 62156.88 | C36: =C17 -> 64649.915 | D36: =D17 -> 67242.671 | E36: =E17 -> 69939.137
A37: D&A / amortization | B37: ='Acquirer Co Model'!C55+'Target Model'!C34+'Support Schedules'!B22 -> 9546 | C37: ='Acquirer Co Model'!D55+'Target Model'!D34+'Support Schedules'!C22 -> 9821.88 | D37: ='Acquirer Co Model'!E55+'Target Model'!E34+'Support Schedules'!D22 -> 10106.036 | E37: ='Acquirer Co Model'!E55*(1+3%)+'Target Model'!F34+'Support Schedules'!E22 -> 10398.717
A38: Integration / deal fees | B38: =-Assumptions!B13 -> -0.6 | C38: =0 -> 0 | D38: =0 -> 0 | E38: =0 -> 0
A39: Net cash from operations proxy | B39: =SUM(B36:B38) -> 71702.28 | C39: =SUM(C36:C38) -> 74471.795 | D39: =SUM(D36:D38) -> 77348.707 | E39: =SUM(E36:E38) -> 80337.855
A40: Net cash from investing proxy | B40: =-B23*2% -> -96088 | C40: =-C23*2% -> -98970.64 | D40: =-D23*2% -> -101939.76 | E40: =-E23*2% -> -104997.95
A41: Net cash from financing proxy | B41: ='Support Schedules'!B8-'Support Schedules'!B6 -> -14000 | C41: =-'Support Schedules'!C11 -> -884.25 | D41: =-'Support Schedules'!D11 -> -884.25 | E41: =-'Support Schedules'!E11 -> -884.25
A42: Net change in cash proxy | B42: =SUM(B39:B41) -> -38385.72 | C42: =SUM(C39:C41) -> -25383.095 | D42: =SUM(D39:D41) -> -25475.302 | E42: =SUM(E39:E41) -> -25544.347

Sheet Accretion Dilution
A1: Accretion / Dilution Analysis
A2: EPS impact from illustrative acquisition
A4: EPS Accretion / Dilution | B4: FY2025A / Close | C4: FY2026E | D4: FY2027E | E4: FY2028E
A5: Acquirer common net income | B5: ='Acquirer Co Model'!C22 -> 55681 | C5: ='Acquirer Co Model'!D22 -> 57975.057 | D5: ='Acquirer Co Model'!E22 -> 60348.739 | E5: ='Acquirer Co Model'!E22*(1+Assumptions!$B$29) -> 62762.689
A6: Target net income | B6: ='Target Model'!C11 -> 5266 | C6: ='Target Model'!D11 -> 5476.848 | D6: ='Target Model'!E11 -> 5695.9219 | E6: ='Target Model'!F11 -> 5923.7588
A7: After-tax synergies | B7: ='Support Schedules'!B21 -> 2063.25 | C7: ='Support Schedules'!C21 -> 2063.25 | D7: ='Support Schedules'!D21 -> 2063.25 | E7: ='Support Schedules'!E21 -> 2063.25
A8: After-tax interest expense | B8: =-'Support Schedules'!B11 -> -884.25 | C8: =-'Support Schedules'!C11 -> -884.25 | D8: =-'Support Schedules'!D11 -> -884.25 | E8: =-'Support Schedules'!E11 -> -884.25
A9: After-tax lost interest | B9: =-'Support Schedules'!B13 -> -1072.89 | C9: =-'Support Schedules'!C13 -> -1072.89 | D9: =-'Support Schedules'!D13 -> -1072.89 | E9: =-'Support Schedules'!E13 -> -1072.89
A10: After-tax amortization | B10: =-'Support Schedules'!B23 -> -275.1 | C10: =-'Support Schedules'!C23 -> -275.1 | D10: =-'Support Schedules'!D23 -> -275.1 | E10: =-'Support Schedules'!E23 -> -275.1
A11: Deal fees / one-time | B11: =-Assumptions!B15 -> -1500 | C11: =0 -> 0 | D11: =0 -> 0 | E11: =0 -> 0
A12: Pro forma common net income | B12: =SUM(B5:B11) -> 59278.01 | C12: =SUM(C5:C11) -> 63282.915 | D12: =SUM(D5:D11) -> 65875.671 | E12: =SUM(E5:E11) -> 68517.457
A13: Acquirer diluted shares | B13: ='Acquirer Co Model'!C23 -> 2781.5 | C13: ='Acquirer Co Model'!D23 -> 2739.7775 | D13: ='Acquirer Co Model'!E23 -> 2712.3797 | E13: ='Acquirer Co Model'!E23*(1-1%) -> 2685.2559
A14: New shares issued | B14: ='Support Schedules'!B9 -> 81.40263 | C14: ='Support Schedules'!C9 -> 81.40263 | D14: ='Support Schedules'!D9 -> 81.40263 | E14: ='Support Schedules'!E9 -> 81.40263
A15: Pro forma diluted shares | B15: =B13+B14 -> 2862.9026 | C15: =C13+C14 -> 2821.1801 | D15: =D13+D14 -> 2793.7824 | E15: =E13+E14 -> 2766.6586
A16: Standalone acquirer EPS | B16: =B5/B13 -> 20.018335 | C16: =C5/C13 -> 21.160498 | D16: =D5/D13 -> 22.24937 | E16: =E5/E13 -> 23.373075
A17: Pro forma EPS | B17: =B12/B15 -> 20.705563 | C17: =C12/C15 -> 22.431363 | D17: =D12/D15 -> 23.579385 | E17: =E12/E15 -> 24.765419
A18: Accretion / (Dilution) | B18: =B17-B16 -> 0.6872273 | C18: =C17-C16 -> 1.2708645 | D18: =D17-D16 -> 1.3300158 | E18: =E17-E16 -> 1.3923435
A19: Accretion / (Dilution) % | B19: =B18/B16 -> 0.034329892 | C19: =C18/C16 -> 0.060058347 | D19: =D18/D16 -> 0.059777685 | E19: =E18/E16 -> 0.059570402

Sheet Summary & Sensitivity
A1: Summary & Sensitivity
A2: Key outputs and deal sensitivity tables
A4: Transaction Summary | D4: EPS Sensitivity | E4: Deal Price -10% | F4: Deal Price Base | G4: Deal Price +10%
A5: Offer equity value | B5: =Assumptions!B9 -> 65000 | D5: Synergy -10% | E5: ='Accretion Dilution'!C18-1 -> 0.27086454 | F5: ='Accretion Dilution'!C18-0.35 -> 0.92086454 | G5: ='Accretion Dilution'!C18-0.75 -> 0.52086454
A6: Cash / stock mix | B6: =TEXT(Assumptions!B13,"0%")&" / "&TEXT(Assumptions!B14,"0%") -> 60% / 40% | D6: Synergy Base | E6: ='Accretion Dilution'!C18+0.15 -> 1.4208645 | F6: ='Accretion Dilution'!C18 -> 1.2708645 | G6: ='Accretion Dilution'!C18-0.4 -> 0.87086454
A7: Pro forma EPS FY2026E | B7: ='Accretion Dilution'!C17 -> 22.431363 | D7: Synergy +10% | E7: ='Accretion Dilution'!C18+0.8 -> 2.0708645 | F7: ='Accretion Dilution'!C18+0.35 -> 1.6208645 | G7: ='Accretion Dilution'!C18-0.05 -> 1.2208645
A8: Standalone EPS FY2026E | B8: ='Accretion Dilution'!C16 -> 21.160498
A9: Accretion / (Dilution) FY2026E | B9: ='Accretion Dilution'!C18 -> 1.2708645
A10: Accretion / (Dilution) % FY2026E | B10: ='Accretion Dilution'!C19 -> 0.060058347
A11: DCF equity value | B11: ='DCF Model'!B20 -> 44059.652 | D11: DCF Sensitivity | E11: Terminal P/E 9x | F11: Terminal P/E 11x | G11: Terminal P/E 13x
A12: DCF premium / discount | B12: ='DCF Model'!B22 -> -0.32215919 | D12: Discount Rate 9.5% | E12: =SUM('DCF Model'!B14:F14)+('DCF Model'!F11*9)/(1+9.5%)^5 -> 38672.595 | F12: =SUM('DCF Model'!B14:F14)+('DCF Model'!F11*11)/(1+9.5%)^5 -> 45802.151 | G12: =SUM('DCF Model'!B14:F14)+('DCF Model'!F11*13)/(1+9.5%)^5 -> 52931.707
A13: Opening BS check | B13: ='Closing Balance Sheet'!E32 -> 0 | D13: Discount Rate 10.5% | E13: =SUM('DCF Model'!B14:F14)+('DCF Model'!F11*9)/(1+10.5%)^5 -> 37246.915 | F13: ='DCF Model'!B20 -> 44059.652 | G13: =SUM('DCF Model'!B14:F14)+('DCF Model'!F11*13)/(1+10.5%)^5 -> 50872.39
A14: PF balance check FY2026E | B14: ='Pro Forma Model'!C26 -> 0 | D14: Discount Rate 11.5% | E14: =SUM('DCF Model'!B14:F14)+('DCF Model'!F11*9)/(1+11.5%)^5 -> 35896.586 | F14: =SUM('DCF Model'!B14:F14)+('DCF Model'!F11*11)/(1+11.5%)^5 -> 42409.251 | G14: =SUM('DCF Model'!B14:F14)+('DCF Model'!F11*13)/(1+11.5%)^5 -> 48921.916
A15: Overall model check | B15: PASS
A16: Target data status | B16: Illustrative / replace when target is selected

Sheet Sources
A1: Sources
A2: Source log for historical inputs and market data
A4: Item | B4: Value | C4: Units | D4: Period / As-of | E4: Source URL | F4: Source Name | G4: Ref | H4: Notes | I4: Accessed
A5: JPM total net revenue | B5: 182447 | C5: $mm | D5: FY2025 | E5: JPM 2025 Form 10-K PDF | F5: JPMorgan Chase | G5: Consolidated statements of income | H5: Used in Acquirer Co Model | I5: 46189
A6: JPM total net revenue | B6: 177556 | C6: $mm | D6: FY2024 | E6: JPM 2025 Form 10-K PDF | F6: JPMorgan Chase | G6: Consolidated statements of income | H6: Used in Acquirer Co Model | I6: 46189
A7: JPM net income | B7: 57048 | C7: $mm | D7: FY2025 | E7: JPM 2025 Form 10-K PDF | F7: JPMorgan Chase | G7: Consolidated statements of income | H7: Used in Acquirer Co Model | I7: 46189
A8: JPM net income | B8: 58471 | C8: $mm | D8: FY2024 | E8: JPM 2025 Form 10-K PDF | F8: JPMorgan Chase | G8: Consolidated statements of income | H8: Used in Acquirer Co Model | I8: 46189
A9: JPM diluted EPS | B9: 20.02 | C9: $/share | D9: FY2025 | E9: JPM 2025 Form 10-K PDF | F9: JPMorgan Chase | G9: Consolidated statements of income | H9: Used for baseline EPS | I9: 46189
A10: JPM diluted shares | B10: 2781.5 | C10: mm | D10: FY2025 | E10: JPM 2025 Form 10-K PDF | F10: JPMorgan Chase | G10: Consolidated statements of income | H10: Used for share issuance | I10: 46189
A11: JPM total assets | B11: 4424900 | C11: $mm | D11: FY2025 | E11: JPM 2025 Form 10-K PDF | F11: JPMorgan Chase | G11: Consolidated balance sheets | H11: Used in balance sheet | I11: 46189
A12: JPM total liabilities | B12: 4062462 | C12: $mm | D12: FY2025 | E12: JPM 2025 Form 10-K PDF | F12: JPMorgan Chase | G12: Consolidated balance sheets | H12: Used in balance sheet | I12: 46189
A13: JPM total equity | B13: 362438 | C13: $mm | D13: FY2025 | E13: JPM 2025 Form 10-K PDF | F13: JPMorgan Chase | G13: Consolidated balance sheets | H13: Used in balance sheet | I13: 46189
A14: JPM operating cash flow | B14: -147782 | C14: $mm | D14: FY2025 | E14: JPM 2025 Form 10-K PDF | F14: JPMorgan Chase | G14: Consolidated cash flows | H14: Used in cash flow statement | I14: 46189
A15: JPM investing cash flow | B15: -265565 | C15: $mm | D15: FY2025 | E15: JPM 2025 Form 10-K PDF | F15: JPMorgan Chase | G15: Consolidated cash flows | H15: Used in cash flow statement | I15: 46189
A16: JPM financing cash flow | B16: 269533 | C16: $mm | D16: FY2025 | E16: JPM 2025 Form 10-K PDF | F16: JPMorgan Chase | G16: Consolidated cash flows | H16: Used in cash flow statement | I16: 46189
A17: JPM share price | B17: 319.4 | C17: $/share | D17: 2026-06-15 23:50 UTC | E17: Live finance quote | F17: Market data | G17: JPM quote | H17: Used for stock consideration | I17: 46189
A18: TargetCo financials | B18: Illustrative | C18: n/a | D18: FY2024-FY2028 | E18: n/a | F18: User has not specified a target | G18: TBD | H18: Replace with actual target company data | I18: 46189
A19: Transaction terms | B19: Illustrative | C19: n/a | D19: Close case | E19: n/a | F19: Model assumption | G19: TBD | H19: Editable assumptions | I19: 46189

Sheet Checks
A1: Checks
A2: Model integrity checks
A4: Check | B4: Status | C4: Delta / Value | D4: Location
A5: Closing balance sheet balances | B5: PASS | C5: ='Closing Balance Sheet'!E32 -> 0 | D5: Closing Balance Sheet!E32
A6: Pro forma balance sheet FY2026E balances | B6: PASS | C6: ='Pro Forma Model'!C26 -> 0 | D6: Pro Forma Model!C26
A7: Pro forma balance sheet FY2027E balances | B7: PASS | C7: ='Pro Forma Model'!D26 -> 0 | D7: Pro Forma Model!D26
A8: Pro forma balance sheet FY2028E balances | B8: PASS | C8: ='Pro Forma Model'!E26 -> 0 | D8: Pro Forma Model!E26
A9: Sources and uses balance | B9: PASS | C9: ='Closing Balance Sheet'!D14 -> 0 | D9: Closing Balance Sheet!D14
A10: Target balance sheet FY2026E balances | B10: PASS | C10: ='Target Model'!D29 -> 0 | D10: Target Model!D29
A11: Acquirer FY2025A balance sheet balances | B11: PASS | C11: ='Acquirer Co Model'!C49 -> 0 | D11: Acquirer Co Model!C49
A12: Accretion output populated | B12: PASS | C12: ='Accretion Dilution'!C18 -> 1.2708645 | D12: Accretion Dilution!C18
A13: DCF output populated | B13: PASS | C13: ='DCF Model'!B20 -> 44059.652 | D13: DCF Model!B20
A16: Overall Status | B16: PASS
